<?xml version="1.0" ?>
<!-- =================================================================================== -->
<!-- |    This document was autogenerated by xacro from korus_v3_world.urdf.xacro      | -->
<!-- |    EDITING THIS FILE BY HAND IS NOT RECOMMENDED                                 | -->
<!-- =================================================================================== -->
<robot name="korus_v3" xmlns:xacro="http://www.ros.org/wiki/xacro">
  <!--   <include filename="$(find korus_meta)/resources/urdf/omni_drive_base.urdf.xacro"/> -->
  <!-- ************************ Base model ************************* -->
  <link name="local_manip_start"/>
  <joint name="base_position_x_joint" type="prismatic">
    <parent link="local_manip_start"/>
    <child link="base_position_x_link"/>
    <origin rpy="0 0 0" xyz="0.0 0.0 0.0"/>
    <axis xyz="1 0 0"/>
    <limit effort="10" lower="-2.0" upper="2.0" velocity="1.0"/>
  </joint>
  <link name="base_position_x_link"/>
  <joint name="base_position_y_joint" type="prismatic">
    <parent link="base_position_x_link"/>
    <child link="base_position_y_link"/>
    <origin rpy="0 0 0" xyz="0.0 0.0 0.0"/>
    <axis xyz="0 1 0"/>
    <limit effort="10" lower="-2.0" upper="2.0" velocity="1.0"/>
  </joint>
  <link name="base_position_y_link"/>
  <joint name="base_heading_joint" type="revolute">
    <parent link="base_position_y_link"/>
    <child link="base_link"/>
    <origin rpy="0 0 0" xyz="0.0 0.0 0.075"/>
    <axis xyz="0 0 1"/>
    <limit effort="10" lower="-3.14159265359" upper="3.14159265359" velocity="1.0"/>
  </joint>
  <link name="base_link">
    <visual>
      <origin rpy="0 0 0" xyz="0.0 0 0.0875"/>
      <geometry>
        <cylinder length="0.275" radius="0.250"/>
      </geometry>
      <material name="yellow">
        <color rgba="1 1 0.2 1"/>
      </material>
    </visual>
    <collision>
      <origin rpy="0 0 0" xyz="0.0 0 0.0875"/>
      <geometry>
        <cylinder length="0.275" radius="0.250"/>
      </geometry>
      <material name="white">
        <color rgba="1 1 1 1"/>
      </material>
    </collision>
  </link>
  <joint name="wheel_left_joint" type="fixed">
    <parent link="base_link"/>
    <child link="wheel_left_link"/>
    <origin rpy="0 0 1.57079632679" xyz="0.0 0.15 0.0"/>
  </joint>
  <link name="wheel_left_link">
    <visual>
      <geometry>
        <cylinder length="0.03" radius="0.075"/>
      </geometry>
      <origin rpy="0 1.57079632679 0" xyz="0 0 0"/>
      <material name="black">
        <color rgba="0.1 0.1 0.1 1"/>
      </material>
    </visual>
  </link>
  <joint name="wheel_right_joint" type="fixed">
    <parent link="base_link"/>
    <child link="wheel_right_link"/>
    <origin rpy="0 0 1.57079632679" xyz="0.0 -0.15 0.0"/>
  </joint>
  <link name="wheel_right_link">
    <visual>
      <geometry>
        <cylinder length="0.03" radius="0.075"/>
      </geometry>
      <origin rpy="0 1.57079632679 0" xyz="0 0 0"/>
      <material name="black">
        <color rgba="0.1 0.1 0.1 1"/>
      </material>
    </visual>
  </link>
  <joint name="caster_front_left_joint" type="fixed">
    <parent link="base_link"/>
    <child link="caster_front_left_link"/>
    <origin rpy="0 0 1.57079632679" xyz="0.18 0.1 -0.035"/>
  </joint>
  <link name="caster_front_left_link">
    <visual>
      <geometry>
        <cylinder length="0.02" radius="0.04"/>
      </geometry>
      <origin rpy="0 1.57079632679 0" xyz="0 0 0"/>
      <material name="black">
        <color rgba="0.1 0.1 0.1 1"/>
      </material>
    </visual>
  </link>
  <joint name="caster_front_right_joint" type="fixed">
    <parent link="base_link"/>
    <child link="caster_front_right_link"/>
    <origin rpy="0 0 1.57079632679" xyz="0.18 -0.1 -0.035"/>
  </joint>
  <link name="caster_front_right_link">
    <visual>
      <geometry>
        <cylinder length="0.02" radius="0.04"/>
      </geometry>
      <origin rpy="0 1.57079632679 0" xyz="0 0 0"/>
      <material name="black">
        <color rgba="0.1 0.1 0.1 1"/>
      </material>
    </visual>
  </link>
  <joint name="caster_back_left_joint" type="fixed">
    <parent link="base_link"/>
    <child link="caster_back_left_link"/>
    <origin rpy="0 0 1.57079632679" xyz="-0.18 0.1 -0.035"/>
  </joint>
  <link name="caster_back_left_link">
    <visual>
      <geometry>
        <cylinder length="0.02" radius="0.04"/>
      </geometry>
      <origin rpy="0 1.57079632679 0" xyz="0 0 0"/>
      <material name="black">
        <color rgba="0.1 0.1 0.1 1"/>
      </material>
    </visual>
  </link>
  <joint name="caster_back_right_joint" type="fixed">
    <parent link="base_link"/>
    <child link="caster_back_right_link"/>
    <origin rpy="0 0 1.57079632679" xyz="-0.18 -0.1 -0.035"/>
  </joint>
  <link name="caster_back_right_link">
    <visual>
      <geometry>
        <cylinder length="0.02" radius="0.04"/>
      </geometry>
      <origin rpy="0 1.57079632679 0" xyz="0 0 0"/>
      <material name="black">
        <color rgba="0.1 0.1 0.1 1"/>
      </material>
    </visual>
  </link>
</robot>
